Traceback (most recent call last):
  File "train.py", line 272, in <module>
    pl_train_acc, nl_train_acc = train(args, epoch, num_classes, train_loader, model, train_loss, optimizer, optimizer_u, optimizer_v)
  File "train.py", line 87, in train
    loss_pl = train_criterion(indexes, output1, None, target, None, True)
  File "/home/ubuntu/miniconda3/lib/python3.8/site-packages/torch/nn/modules/module.py", line 1110, in _call_impl
    return forward_call(*input, **kwargs)
  File "/home/ubuntu/work/dep/zcc/last_version_v1/loss.py", line 69, in forward
    return self.forward_wo_nl(index, outputs, label)
  File "/home/ubuntu/work/dep/zcc/last_version_v1/loss.py", line 105, in forward_wo_nl
    label_one_hot = self.soft_to_hard(output.detach())
  File "/home/ubuntu/work/dep/zcc/last_version_v1/loss.py", line 82, in soft_to_hard
    return (torch.zeros(len(x), self.num_classes)).cuda().scatter_(1, (x.argmax(dim=1)).view(-1,1), 1)
KeyboardInterrupt
Traceback (most recent call last):
  File "<frozen importlib._bootstrap_external>", line 1281, in _path_importer_cache
KeyError: '/home/ubuntu/work/dep/zcc/last_version_v1'

During handling of the above exception, another exception occurred:

Traceback (most recent call last):
  File "train.py", line 3, in <module>
    import torch
  File "<frozen importlib._bootstrap>", line 991, in _find_and_load
  File "<frozen importlib._bootstrap>", line 971, in _find_and_load_unlocked
  File "<frozen importlib._bootstrap>", line 914, in _find_spec
  File "<frozen importlib._bootstrap_external>", line 1342, in find_spec
  File "<frozen importlib._bootstrap_external>", line 1311, in _get_spec
  File "<frozen importlib._bootstrap_external>", line 1283, in _path_importer_cache
  File "<frozen importlib._bootstrap_external>", line 1261, in _path_hooks
KeyboardInterrupt
Traceback (most recent call last):
  File "train.py", line 272, in <module>
    
  File "train.py", line 87, in train
    loss_pl = train_criterion(indexes, output1, None, target, None, True)
  File "/home/ubuntu/miniconda3/lib/python3.8/site-packages/torch/nn/modules/module.py", line 1110, in _call_impl
    return forward_call(*input, **kwargs)
  File "/home/ubuntu/work/dep/zcc/last_version_v1/loss.py", line 69, in forward
    return self.forward_wo_nl(index, outputs, label)
  File "/home/ubuntu/work/dep/zcc/last_version_v1/loss.py", line 105, in forward_wo_nl
    label_one_hot = self.soft_to_hard(output.detach())
  File "/home/ubuntu/work/dep/zcc/last_version_v1/loss.py", line 82, in soft_to_hard
    return (torch.zeros(len(x), self.num_classes)).cuda().scatter_(1, (x.argmax(dim=1)).view(-1,1), 1)
KeyboardInterrupt
Fatal Python error: init_import_size: Failed to import the site module
Python runtime state: initialized
Traceback (most recent call last):
  File "/home/ubuntu/miniconda3/lib/python3.8/site.py", line 580, in <module>
    main()
  File "/home/ubuntu/miniconda3/lib/python3.8/site.py", line 567, in main
    known_paths = addsitepackages(known_paths)
  File "/home/ubuntu/miniconda3/lib/python3.8/site.py", line 350, in addsitepackages
    addsitedir(sitedir, known_paths)
  File "/home/ubuntu/miniconda3/lib/python3.8/site.py", line 208, in addsitedir
    addpackage(sitedir, name, known_paths)
  File "/home/ubuntu/miniconda3/lib/python3.8/site.py", line 169, in addpackage
    exec(line)
  File "<string>", line 1, in <module>
  File "/home/ubuntu/miniconda3/lib/python3.8/importlib/util.py", line 2, in <module>
    from . import abc
  File "<frozen importlib._bootstrap>", line 991, in _find_and_load
  File "<frozen importlib._bootstrap>", line 975, in _find_and_load_unlocked
  File "<frozen importlib._bootstrap>", line 671, in _load_unlocked
  File "<frozen importlib._bootstrap_external>", line 779, in exec_module
  File "<frozen importlib._bootstrap_external>", line 911, in get_code
  File "<frozen importlib._bootstrap_external>", line 580, in _compile_bytecode
KeyboardInterrupt
Traceback (most recent call last):
  File "train.py", line 289, in <module>
    print("Learning rate: {}.".format(optimizer.state_dict()['param_groups'][0]['lr']))
  File "train.py", line 167, in evaluate
    for images, _, labels, indexes, _ in test_loader:
  File "/home/ubuntu/miniconda3/lib/python3.8/site-packages/torch/utils/data/dataloader.py", line 530, in __next__
    data = self._next_data()
  File "/home/ubuntu/miniconda3/lib/python3.8/site-packages/torch/utils/data/dataloader.py", line 1207, in _next_data
    idx, data = self._get_data()
  File "/home/ubuntu/miniconda3/lib/python3.8/site-packages/torch/utils/data/dataloader.py", line 1173, in _get_data
    success, data = self._try_get_data()
  File "/home/ubuntu/miniconda3/lib/python3.8/site-packages/torch/utils/data/dataloader.py", line 1011, in _try_get_data
    data = self._data_queue.get(timeout=timeout)
  File "/home/ubuntu/miniconda3/lib/python3.8/multiprocessing/queues.py", line 116, in get
    return _ForkingPickler.loads(res)
  File "/home/ubuntu/miniconda3/lib/python3.8/site-packages/torch/multiprocessing/reductions.py", line 295, in rebuild_storage_fd
    fd = df.detach()
  File "/home/ubuntu/miniconda3/lib/python3.8/multiprocessing/resource_sharer.py", line 57, in detach
    with _resource_sharer.get_connection(self._id) as conn:
  File "/home/ubuntu/miniconda3/lib/python3.8/multiprocessing/resource_sharer.py", line 87, in get_connection
    c = Client(address, authkey=process.current_process().authkey)
  File "/home/ubuntu/miniconda3/lib/python3.8/multiprocessing/connection.py", line 508, in Client
    answer_challenge(c, authkey)
  File "/home/ubuntu/miniconda3/lib/python3.8/multiprocessing/connection.py", line 757, in answer_challenge
    response = connection.recv_bytes(256)        # reject large message
  File "/home/ubuntu/miniconda3/lib/python3.8/multiprocessing/connection.py", line 216, in recv_bytes
    buf = self._recv_bytes(maxlength)
  File "/home/ubuntu/miniconda3/lib/python3.8/multiprocessing/connection.py", line 414, in _recv_bytes
    buf = self._recv(4)
  File "/home/ubuntu/miniconda3/lib/python3.8/multiprocessing/connection.py", line 379, in _recv
    chunk = read(handle, remaining)
KeyboardInterrupt
Fatal Python error: init_import_size: Failed to import the site module
Python runtime state: initialized
Traceback (most recent call last):
  File "/home/ubuntu/miniconda3/lib/python3.8/site.py", line 580, in <module>
    main()
  File "/home/ubuntu/miniconda3/lib/python3.8/site.py", line 567, in main
    known_paths = addsitepackages(known_paths)
  File "/home/ubuntu/miniconda3/lib/python3.8/site.py", line 350, in addsitepackages
    addsitedir(sitedir, known_paths)
  File "/home/ubuntu/miniconda3/lib/python3.8/site.py", line 208, in addsitedir
    addpackage(sitedir, name, known_paths)
  File "/home/ubuntu/miniconda3/lib/python3.8/site.py", line 169, in addpackage
    exec(line)
  File "<string>", line 1, in <module>
  File "/home/ubuntu/miniconda3/lib/python3.8/importlib/util.py", line 14, in <module>
    from contextlib import contextmanager
  File "/home/ubuntu/miniconda3/lib/python3.8/contextlib.py", line 5, in <module>
    from collections import deque
  File "/home/ubuntu/miniconda3/lib/python3.8/collections/__init__.py", line 78, in <module>
    class _Link(object):
KeyboardInterrupt
Traceback (most recent call last):
  File "train.py", line 283, in <module>
    time_curr = time.time()
  File "train.py", line 119, in train
    nl_probs.extend(F.softmax(logits2, dim=1)[range(len(label)), label].cpu().detach().numpy().tolist())
KeyboardInterrupt
Fatal Python error: init_import_size: Failed to import the site module
Python runtime state: initialized
Traceback (most recent call last):
  File "/home/ubuntu/miniconda3/lib/python3.8/site.py", line 580, in <module>
    main()
  File "/home/ubuntu/miniconda3/lib/python3.8/site.py", line 567, in main
    known_paths = addsitepackages(known_paths)
  File "/home/ubuntu/miniconda3/lib/python3.8/site.py", line 350, in addsitepackages
    addsitedir(sitedir, known_paths)
  File "/home/ubuntu/miniconda3/lib/python3.8/site.py", line 208, in addsitedir
    addpackage(sitedir, name, known_paths)
  File "/home/ubuntu/miniconda3/lib/python3.8/site.py", line 169, in addpackage
    exec(line)
  File "<string>", line 1, in <module>
  File "/home/ubuntu/miniconda3/lib/python3.8/importlib/util.py", line 14, in <module>
    from contextlib import contextmanager
  File "/home/ubuntu/miniconda3/lib/python3.8/contextlib.py", line 6, in <module>
    from functools import wraps
  File "/home/ubuntu/miniconda3/lib/python3.8/functools.py", line 657, in <module>
    def _c3_merge(sequences):
KeyboardInterrupt
